2021-05-21 23:36:07,581 INFO: Gym accounting [in /home/kroof/PycharmProjects/Gym_accounting_Flask/app/__init__.py:41]
2021-05-21 23:36:43,230 INFO: Gym accounting [in /home/kroof/PycharmProjects/Gym_accounting_Flask/app/__init__.py:41]
2021-05-21 23:39:53,944 INFO: Gym accounting [in /home/kroof/PycharmProjects/Gym_accounting_Flask/app/__init__.py:41]
2021-05-21 23:40:14,008 INFO: Gym accounting [in /home/kroof/PycharmProjects/Gym_accounting_Flask/app/__init__.py:41]
2021-05-21 23:40:42,457 INFO: Gym accounting [in /home/kroof/PycharmProjects/Gym_accounting_Flask/app/__init__.py:41]
2021-05-21 23:42:00,846 INFO: Gym accounting [in /home/kroof/PycharmProjects/Gym_accounting_Flask/app/__init__.py:41]
2021-05-21 23:43:02,360 INFO: Gym accounting [in /home/kroof/PycharmProjects/Gym_accounting_Flask/app/__init__.py:41]
2021-05-21 23:44:54,793 INFO: Gym accounting [in /home/kroof/PycharmProjects/Gym_accounting_Flask/app/__init__.py:41]
2021-05-21 23:44:56,715 ERROR: Exception on /payment [POST] [in /home/kroof/PycharmProjects/adminFor/venv/lib/python3.8/site-packages/flask/app.py:1891]
Traceback (most recent call last):
  File "/home/kroof/PycharmProjects/adminFor/venv/lib/python3.8/site-packages/flask/app.py", line 2447, in wsgi_app
    response = self.full_dispatch_request()
  File "/home/kroof/PycharmProjects/adminFor/venv/lib/python3.8/site-packages/flask/app.py", line 1952, in full_dispatch_request
    rv = self.handle_user_exception(e)
  File "/home/kroof/PycharmProjects/adminFor/venv/lib/python3.8/site-packages/flask/app.py", line 1821, in handle_user_exception
    reraise(exc_type, exc_value, tb)
  File "/home/kroof/PycharmProjects/adminFor/venv/lib/python3.8/site-packages/flask/_compat.py", line 39, in reraise
    raise value
  File "/home/kroof/PycharmProjects/adminFor/venv/lib/python3.8/site-packages/flask/app.py", line 1950, in full_dispatch_request
    rv = self.dispatch_request()
  File "/home/kroof/PycharmProjects/adminFor/venv/lib/python3.8/site-packages/flask/app.py", line 1936, in dispatch_request
    return self.view_functions[rule.endpoint](**req.view_args)
  File "/home/kroof/PycharmProjects/adminFor/venv/lib/python3.8/site-packages/flask_login/utils.py", line 272, in decorated_view
    return func(*args, **kwargs)
  File "/home/kroof/PycharmProjects/Gym_accounting_Flask/app/routes.py", line 156, in payment
    dateTemp = form.DateOfStart.data.format(datetime)
AttributeError: 'datetime.date' object has no attribute 'format'
2021-05-21 23:45:15,416 ERROR: Exception on /payment [POST] [in /home/kroof/PycharmProjects/adminFor/venv/lib/python3.8/site-packages/flask/app.py:1891]
Traceback (most recent call last):
  File "/home/kroof/PycharmProjects/adminFor/venv/lib/python3.8/site-packages/flask/app.py", line 2447, in wsgi_app
    response = self.full_dispatch_request()
  File "/home/kroof/PycharmProjects/adminFor/venv/lib/python3.8/site-packages/flask/app.py", line 1952, in full_dispatch_request
    rv = self.handle_user_exception(e)
  File "/home/kroof/PycharmProjects/adminFor/venv/lib/python3.8/site-packages/flask/app.py", line 1821, in handle_user_exception
    reraise(exc_type, exc_value, tb)
  File "/home/kroof/PycharmProjects/adminFor/venv/lib/python3.8/site-packages/flask/_compat.py", line 39, in reraise
    raise value
  File "/home/kroof/PycharmProjects/adminFor/venv/lib/python3.8/site-packages/flask/app.py", line 1950, in full_dispatch_request
    rv = self.dispatch_request()
  File "/home/kroof/PycharmProjects/adminFor/venv/lib/python3.8/site-packages/flask/app.py", line 1936, in dispatch_request
    return self.view_functions[rule.endpoint](**req.view_args)
  File "/home/kroof/PycharmProjects/adminFor/venv/lib/python3.8/site-packages/flask_login/utils.py", line 272, in decorated_view
    return func(*args, **kwargs)
  File "/home/kroof/PycharmProjects/Gym_accounting_Flask/app/routes.py", line 156, in payment
    dateTemp = form.DateOfStart.data
AttributeError: 'datetime.date' object has no attribute 'format'
2021-05-21 23:45:48,312 INFO: Gym accounting [in /home/kroof/PycharmProjects/Gym_accounting_Flask/app/__init__.py:41]
2021-05-21 23:46:00,070 ERROR: Exception on /payment [POST] [in /home/kroof/PycharmProjects/adminFor/venv/lib/python3.8/site-packages/flask/app.py:1891]
Traceback (most recent call last):
  File "/home/kroof/PycharmProjects/adminFor/venv/lib/python3.8/site-packages/flask/app.py", line 2447, in wsgi_app
    response = self.full_dispatch_request()
  File "/home/kroof/PycharmProjects/adminFor/venv/lib/python3.8/site-packages/flask/app.py", line 1952, in full_dispatch_request
    rv = self.handle_user_exception(e)
  File "/home/kroof/PycharmProjects/adminFor/venv/lib/python3.8/site-packages/flask/app.py", line 1821, in handle_user_exception
    reraise(exc_type, exc_value, tb)
  File "/home/kroof/PycharmProjects/adminFor/venv/lib/python3.8/site-packages/flask/_compat.py", line 39, in reraise
    raise value
  File "/home/kroof/PycharmProjects/adminFor/venv/lib/python3.8/site-packages/flask/app.py", line 1950, in full_dispatch_request
    rv = self.dispatch_request()
  File "/home/kroof/PycharmProjects/adminFor/venv/lib/python3.8/site-packages/flask/app.py", line 1936, in dispatch_request
    return self.view_functions[rule.endpoint](**req.view_args)
  File "/home/kroof/PycharmProjects/adminFor/venv/lib/python3.8/site-packages/flask_login/utils.py", line 272, in decorated_view
    return func(*args, **kwargs)
  File "/home/kroof/PycharmProjects/Gym_accounting_Flask/app/routes.py", line 157, in payment
    dateS = datetime.datetime.strptime(dateTemp, "%d/%m/%Y")
AttributeError: type object 'datetime.datetime' has no attribute 'datetime'
2021-05-21 23:46:13,449 INFO: Gym accounting [in /home/kroof/PycharmProjects/Gym_accounting_Flask/app/__init__.py:41]
2021-05-21 23:46:26,231 ERROR: Exception on /payment [POST] [in /home/kroof/PycharmProjects/adminFor/venv/lib/python3.8/site-packages/flask/app.py:1891]
Traceback (most recent call last):
  File "/home/kroof/PycharmProjects/adminFor/venv/lib/python3.8/site-packages/flask/app.py", line 2447, in wsgi_app
    response = self.full_dispatch_request()
  File "/home/kroof/PycharmProjects/adminFor/venv/lib/python3.8/site-packages/flask/app.py", line 1952, in full_dispatch_request
    rv = self.handle_user_exception(e)
  File "/home/kroof/PycharmProjects/adminFor/venv/lib/python3.8/site-packages/flask/app.py", line 1821, in handle_user_exception
    reraise(exc_type, exc_value, tb)
  File "/home/kroof/PycharmProjects/adminFor/venv/lib/python3.8/site-packages/flask/_compat.py", line 39, in reraise
    raise value
  File "/home/kroof/PycharmProjects/adminFor/venv/lib/python3.8/site-packages/flask/app.py", line 1950, in full_dispatch_request
    rv = self.dispatch_request()
  File "/home/kroof/PycharmProjects/adminFor/venv/lib/python3.8/site-packages/flask/app.py", line 1936, in dispatch_request
    return self.view_functions[rule.endpoint](**req.view_args)
  File "/home/kroof/PycharmProjects/adminFor/venv/lib/python3.8/site-packages/flask_login/utils.py", line 272, in decorated_view
    return func(*args, **kwargs)
  File "/home/kroof/PycharmProjects/Gym_accounting_Flask/app/routes.py", line 157, in payment
    dateS = datetime.strptime(dateTemp, "%d/%m/%Y")
TypeError: strptime() argument 1 must be str, not datetime.date
2021-05-21 23:48:04,198 INFO: Gym accounting [in /home/kroof/PycharmProjects/Gym_accounting_Flask/app/__init__.py:41]
2021-05-21 23:48:18,305 ERROR: Exception on /payment [POST] [in /home/kroof/PycharmProjects/adminFor/venv/lib/python3.8/site-packages/flask/app.py:1891]
Traceback (most recent call last):
  File "/home/kroof/PycharmProjects/adminFor/venv/lib/python3.8/site-packages/flask/app.py", line 2447, in wsgi_app
    response = self.full_dispatch_request()
  File "/home/kroof/PycharmProjects/adminFor/venv/lib/python3.8/site-packages/flask/app.py", line 1952, in full_dispatch_request
    rv = self.handle_user_exception(e)
  File "/home/kroof/PycharmProjects/adminFor/venv/lib/python3.8/site-packages/flask/app.py", line 1821, in handle_user_exception
    reraise(exc_type, exc_value, tb)
  File "/home/kroof/PycharmProjects/adminFor/venv/lib/python3.8/site-packages/flask/_compat.py", line 39, in reraise
    raise value
  File "/home/kroof/PycharmProjects/adminFor/venv/lib/python3.8/site-packages/flask/app.py", line 1950, in full_dispatch_request
    rv = self.dispatch_request()
  File "/home/kroof/PycharmProjects/adminFor/venv/lib/python3.8/site-packages/flask/app.py", line 1936, in dispatch_request
    return self.view_functions[rule.endpoint](**req.view_args)
  File "/home/kroof/PycharmProjects/adminFor/venv/lib/python3.8/site-packages/flask_login/utils.py", line 272, in decorated_view
    return func(*args, **kwargs)
  File "/home/kroof/PycharmProjects/Gym_accounting_Flask/app/routes.py", line 157, in payment
    dateS = datetime.strptime(dateTemp, "%d/%m/%Y")
  File "/usr/lib/python3.8/_strptime.py", line 568, in _strptime_datetime
    tt, fraction, gmtoff_fraction = _strptime(data_string, format)
  File "/usr/lib/python3.8/_strptime.py", line 349, in _strptime
    raise ValueError("time data %r does not match format %r" %
ValueError: time data '2021-05-21' does not match format '%d/%m/%Y'
2021-05-21 23:48:59,309 INFO: Gym accounting [in /home/kroof/PycharmProjects/Gym_accounting_Flask/app/__init__.py:41]
