2021-05-22 15:30:44,514 ERROR: Exception on /payment [GET] [in /home/kroof/PycharmProjects/adminFor/venv/lib/python3.8/site-packages/flask/app.py:1891]
Traceback (most recent call last):
  File "/home/kroof/PycharmProjects/adminFor/venv/lib/python3.8/site-packages/flask/app.py", line 2447, in wsgi_app
    response = self.full_dispatch_request()
  File "/home/kroof/PycharmProjects/adminFor/venv/lib/python3.8/site-packages/flask/app.py", line 1952, in full_dispatch_request
    rv = self.handle_user_exception(e)
  File "/home/kroof/PycharmProjects/adminFor/venv/lib/python3.8/site-packages/flask/app.py", line 1821, in handle_user_exception
    reraise(exc_type, exc_value, tb)
  File "/home/kroof/PycharmProjects/adminFor/venv/lib/python3.8/site-packages/flask/_compat.py", line 39, in reraise
    raise value
  File "/home/kroof/PycharmProjects/adminFor/venv/lib/python3.8/site-packages/flask/app.py", line 1950, in full_dispatch_request
    rv = self.dispatch_request()
  File "/home/kroof/PycharmProjects/adminFor/venv/lib/python3.8/site-packages/flask/app.py", line 1936, in dispatch_request
    return self.view_functions[rule.endpoint](**req.view_args)
  File "/home/kroof/PycharmProjects/adminFor/venv/lib/python3.8/site-packages/flask_login/utils.py", line 272, in decorated_view
    return func(*args, **kwargs)
  File "/home/kroof/PycharmProjects/Gym_accounting_Flask/app/routes.py", line 208, in payment
    return render_template('payment.html', time_id=time_id, coach_id=coach_id, form=form, sub_id=sub_id, sub=sub, time=time)
  File "/home/kroof/PycharmProjects/adminFor/venv/lib/python3.8/site-packages/flask/templating.py", line 137, in render_template
    return _render(
  File "/home/kroof/PycharmProjects/adminFor/venv/lib/python3.8/site-packages/flask/templating.py", line 120, in _render
    rv = template.render(context)
  File "/home/kroof/PycharmProjects/adminFor/venv/lib/python3.8/site-packages/jinja2/environment.py", line 1090, in render
    self.environment.handle_exception()
  File "/home/kroof/PycharmProjects/adminFor/venv/lib/python3.8/site-packages/jinja2/environment.py", line 832, in handle_exception
    reraise(*rewrite_traceback_stack(source=source))
  File "/home/kroof/PycharmProjects/adminFor/venv/lib/python3.8/site-packages/jinja2/_compat.py", line 28, in reraise
    raise value.with_traceback(tb)
  File "/home/kroof/PycharmProjects/Gym_accounting_Flask/app/templates/payment.html", line 1, in top-level template code
    {% extends "base.html" %}
  File "/home/kroof/PycharmProjects/Gym_accounting_Flask/app/templates/base.html", line 41, in top-level template code
    {% block content %}{% endblock %}
  File "/home/kroof/PycharmProjects/Gym_accounting_Flask/app/templates/payment.html", line 4, in block "content"
    <p>Your coach is {{coach.name}} at {{time.partOfDay}}</p>
  File "/home/kroof/PycharmProjects/adminFor/venv/lib/python3.8/site-packages/jinja2/environment.py", line 471, in getattr
    return getattr(obj, attribute)
jinja2.exceptions.UndefinedError: 'coach' is undefined
2021-05-22 15:31:40,108 INFO: Gym accounting [in /home/kroof/PycharmProjects/Gym_accounting_Flask/app/__init__.py:41]
2021-05-22 15:31:41,237 ERROR: Exception on /payment [GET] [in /home/kroof/PycharmProjects/adminFor/venv/lib/python3.8/site-packages/flask/app.py:1891]
Traceback (most recent call last):
  File "/home/kroof/PycharmProjects/adminFor/venv/lib/python3.8/site-packages/flask/app.py", line 2447, in wsgi_app
    response = self.full_dispatch_request()
  File "/home/kroof/PycharmProjects/adminFor/venv/lib/python3.8/site-packages/flask/app.py", line 1952, in full_dispatch_request
    rv = self.handle_user_exception(e)
  File "/home/kroof/PycharmProjects/adminFor/venv/lib/python3.8/site-packages/flask/app.py", line 1821, in handle_user_exception
    reraise(exc_type, exc_value, tb)
  File "/home/kroof/PycharmProjects/adminFor/venv/lib/python3.8/site-packages/flask/_compat.py", line 39, in reraise
    raise value
  File "/home/kroof/PycharmProjects/adminFor/venv/lib/python3.8/site-packages/flask/app.py", line 1950, in full_dispatch_request
    rv = self.dispatch_request()
  File "/home/kroof/PycharmProjects/adminFor/venv/lib/python3.8/site-packages/flask/app.py", line 1936, in dispatch_request
    return self.view_functions[rule.endpoint](**req.view_args)
  File "/home/kroof/PycharmProjects/adminFor/venv/lib/python3.8/site-packages/flask_login/utils.py", line 272, in decorated_view
    return func(*args, **kwargs)
  File "/home/kroof/PycharmProjects/Gym_accounting_Flask/app/routes.py", line 210, in payment
    return render_template('payment.html', time_id=time_id, coach_id=coach_id, form=form, sub_id=sub_id)
  File "/home/kroof/PycharmProjects/adminFor/venv/lib/python3.8/site-packages/flask/templating.py", line 137, in render_template
    return _render(
  File "/home/kroof/PycharmProjects/adminFor/venv/lib/python3.8/site-packages/flask/templating.py", line 120, in _render
    rv = template.render(context)
  File "/home/kroof/PycharmProjects/adminFor/venv/lib/python3.8/site-packages/jinja2/environment.py", line 1090, in render
    self.environment.handle_exception()
  File "/home/kroof/PycharmProjects/adminFor/venv/lib/python3.8/site-packages/jinja2/environment.py", line 832, in handle_exception
    reraise(*rewrite_traceback_stack(source=source))
  File "/home/kroof/PycharmProjects/adminFor/venv/lib/python3.8/site-packages/jinja2/_compat.py", line 28, in reraise
    raise value.with_traceback(tb)
  File "/home/kroof/PycharmProjects/Gym_accounting_Flask/app/templates/payment.html", line 1, in top-level template code
    {% extends "base.html" %}
  File "/home/kroof/PycharmProjects/Gym_accounting_Flask/app/templates/base.html", line 41, in top-level template code
    {% block content %}{% endblock %}
  File "/home/kroof/PycharmProjects/Gym_accounting_Flask/app/templates/payment.html", line 3, in block "content"
    <p>You chose a subscription: {{sub.name}}</p>
  File "/home/kroof/PycharmProjects/adminFor/venv/lib/python3.8/site-packages/jinja2/environment.py", line 471, in getattr
    return getattr(obj, attribute)
jinja2.exceptions.UndefinedError: 'sub' is undefined
2021-05-22 15:32:07,931 INFO: Gym accounting [in /home/kroof/PycharmProjects/Gym_accounting_Flask/app/__init__.py:41]
2021-05-22 15:32:34,131 INFO: Gym accounting [in /home/kroof/PycharmProjects/Gym_accounting_Flask/app/__init__.py:41]
2021-05-22 15:40:45,273 INFO: Gym accounting [in /home/kroof/PycharmProjects/Gym_accounting_Flask/app/__init__.py:41]
2021-05-22 15:43:35,245 INFO: Gym accounting [in /home/kroof/PycharmProjects/Gym_accounting_Flask/app/__init__.py:41]
2021-05-22 15:44:15,131 INFO: Gym accounting [in /home/kroof/PycharmProjects/Gym_accounting_Flask/app/__init__.py:41]
2021-05-22 15:45:34,935 INFO: Gym accounting [in /home/kroof/PycharmProjects/Gym_accounting_Flask/app/__init__.py:41]
2021-05-22 15:46:21,779 INFO: Gym accounting [in /home/kroof/PycharmProjects/Gym_accounting_Flask/app/__init__.py:41]
2021-05-22 17:00:16,625 INFO: Gym accounting [in /home/kroof/PycharmProjects/Gym_accounting_Flask/app/__init__.py:41]
2021-05-22 17:01:03,849 INFO: Gym accounting [in /home/kroof/PycharmProjects/Gym_accounting_Flask/app/__init__.py:41]
2021-05-22 17:02:08,612 INFO: Gym accounting [in /home/kroof/PycharmProjects/Gym_accounting_Flask/app/__init__.py:41]
2021-05-22 17:03:17,215 INFO: Gym accounting [in /home/kroof/PycharmProjects/Gym_accounting_Flask/app/__init__.py:41]
2021-05-22 17:03:28,588 INFO: Gym accounting [in /home/kroof/PycharmProjects/Gym_accounting_Flask/app/__init__.py:41]
2021-05-22 17:03:53,086 INFO: Gym accounting [in /home/kroof/PycharmProjects/Gym_accounting_Flask/app/__init__.py:41]
2021-05-22 17:03:53,792 ERROR: Exception on /coach_room [GET] [in /home/kroof/PycharmProjects/adminFor/venv/lib/python3.8/site-packages/flask/app.py:1891]
Traceback (most recent call last):
  File "/home/kroof/PycharmProjects/adminFor/venv/lib/python3.8/site-packages/flask/app.py", line 2447, in wsgi_app
    response = self.full_dispatch_request()
  File "/home/kroof/PycharmProjects/adminFor/venv/lib/python3.8/site-packages/flask/app.py", line 1952, in full_dispatch_request
    rv = self.handle_user_exception(e)
  File "/home/kroof/PycharmProjects/adminFor/venv/lib/python3.8/site-packages/flask/app.py", line 1821, in handle_user_exception
    reraise(exc_type, exc_value, tb)
  File "/home/kroof/PycharmProjects/adminFor/venv/lib/python3.8/site-packages/flask/_compat.py", line 39, in reraise
    raise value
  File "/home/kroof/PycharmProjects/adminFor/venv/lib/python3.8/site-packages/flask/app.py", line 1950, in full_dispatch_request
    rv = self.dispatch_request()
  File "/home/kroof/PycharmProjects/adminFor/venv/lib/python3.8/site-packages/flask/app.py", line 1936, in dispatch_request
    return self.view_functions[rule.endpoint](**req.view_args)
  File "/home/kroof/PycharmProjects/adminFor/venv/lib/python3.8/site-packages/flask_login/utils.py", line 272, in decorated_view
    return func(*args, **kwargs)
  File "/home/kroof/PycharmProjects/Gym_accounting_Flask/app/routes.py", line 162, in coach_room
    times = sorted(t)
TypeError: '<' not supported between instances of 'Time' and 'Time'
2021-05-22 17:04:13,926 INFO: Gym accounting [in /home/kroof/PycharmProjects/Gym_accounting_Flask/app/__init__.py:41]
2021-05-22 17:15:46,310 INFO: Gym accounting [in /home/kroof/PycharmProjects/Gym_accounting_Flask/app/__init__.py:41]
