2021-05-22 17:15:50,303 ERROR: Exception on /coach_room [GET] [in /home/kroof/PycharmProjects/adminFor/venv/lib/python3.8/site-packages/flask/app.py:1891]
Traceback (most recent call last):
  File "/home/kroof/PycharmProjects/adminFor/venv/lib/python3.8/site-packages/flask/app.py", line 2447, in wsgi_app
    response = self.full_dispatch_request()
  File "/home/kroof/PycharmProjects/adminFor/venv/lib/python3.8/site-packages/flask/app.py", line 1952, in full_dispatch_request
    rv = self.handle_user_exception(e)
  File "/home/kroof/PycharmProjects/adminFor/venv/lib/python3.8/site-packages/flask/app.py", line 1821, in handle_user_exception
    reraise(exc_type, exc_value, tb)
  File "/home/kroof/PycharmProjects/adminFor/venv/lib/python3.8/site-packages/flask/_compat.py", line 39, in reraise
    raise value
  File "/home/kroof/PycharmProjects/adminFor/venv/lib/python3.8/site-packages/flask/app.py", line 1950, in full_dispatch_request
    rv = self.dispatch_request()
  File "/home/kroof/PycharmProjects/adminFor/venv/lib/python3.8/site-packages/flask/app.py", line 1936, in dispatch_request
    return self.view_functions[rule.endpoint](**req.view_args)
  File "/home/kroof/PycharmProjects/adminFor/venv/lib/python3.8/site-packages/flask_login/utils.py", line 272, in decorated_view
    return func(*args, **kwargs)
  File "/home/kroof/PycharmProjects/Gym_accounting_Flask/app/routes.py", line 162, in coach_room
    trainings[i.time_id] = a.user_id
AttributeError: 'list' object has no attribute 'user_id'
2021-05-22 17:16:34,985 INFO: Gym accounting [in /home/kroof/PycharmProjects/Gym_accounting_Flask/app/__init__.py:41]
2021-05-22 17:16:36,733 ERROR: Exception on /coach_room [GET] [in /home/kroof/PycharmProjects/adminFor/venv/lib/python3.8/site-packages/flask/app.py:1891]
Traceback (most recent call last):
  File "/home/kroof/PycharmProjects/adminFor/venv/lib/python3.8/site-packages/flask/app.py", line 2447, in wsgi_app
    response = self.full_dispatch_request()
  File "/home/kroof/PycharmProjects/adminFor/venv/lib/python3.8/site-packages/flask/app.py", line 1952, in full_dispatch_request
    rv = self.handle_user_exception(e)
  File "/home/kroof/PycharmProjects/adminFor/venv/lib/python3.8/site-packages/flask/app.py", line 1821, in handle_user_exception
    reraise(exc_type, exc_value, tb)
  File "/home/kroof/PycharmProjects/adminFor/venv/lib/python3.8/site-packages/flask/_compat.py", line 39, in reraise
    raise value
  File "/home/kroof/PycharmProjects/adminFor/venv/lib/python3.8/site-packages/flask/app.py", line 1950, in full_dispatch_request
    rv = self.dispatch_request()
  File "/home/kroof/PycharmProjects/adminFor/venv/lib/python3.8/site-packages/flask/app.py", line 1936, in dispatch_request
    return self.view_functions[rule.endpoint](**req.view_args)
  File "/home/kroof/PycharmProjects/adminFor/venv/lib/python3.8/site-packages/flask_login/utils.py", line 272, in decorated_view
    return func(*args, **kwargs)
  File "/home/kroof/PycharmProjects/Gym_accounting_Flask/app/routes.py", line 162, in coach_room
    ad = a.user_id
AttributeError: 'list' object has no attribute 'user_id'
2021-05-22 17:17:34,859 INFO: Gym accounting [in /home/kroof/PycharmProjects/Gym_accounting_Flask/app/__init__.py:41]
2021-05-22 17:17:36,369 ERROR: Exception on /coach_room [GET] [in /home/kroof/PycharmProjects/adminFor/venv/lib/python3.8/site-packages/flask/app.py:1891]
Traceback (most recent call last):
  File "/home/kroof/PycharmProjects/adminFor/venv/lib/python3.8/site-packages/flask/app.py", line 2447, in wsgi_app
    response = self.full_dispatch_request()
  File "/home/kroof/PycharmProjects/adminFor/venv/lib/python3.8/site-packages/flask/app.py", line 1952, in full_dispatch_request
    rv = self.handle_user_exception(e)
  File "/home/kroof/PycharmProjects/adminFor/venv/lib/python3.8/site-packages/flask/app.py", line 1821, in handle_user_exception
    reraise(exc_type, exc_value, tb)
  File "/home/kroof/PycharmProjects/adminFor/venv/lib/python3.8/site-packages/flask/_compat.py", line 39, in reraise
    raise value
  File "/home/kroof/PycharmProjects/adminFor/venv/lib/python3.8/site-packages/flask/app.py", line 1950, in full_dispatch_request
    rv = self.dispatch_request()
  File "/home/kroof/PycharmProjects/adminFor/venv/lib/python3.8/site-packages/flask/app.py", line 1936, in dispatch_request
    return self.view_functions[rule.endpoint](**req.view_args)
  File "/home/kroof/PycharmProjects/adminFor/venv/lib/python3.8/site-packages/flask_login/utils.py", line 272, in decorated_view
    return func(*args, **kwargs)
  File "/home/kroof/PycharmProjects/Gym_accounting_Flask/app/routes.py", line 164, in coach_room
    return render_template('coach_room.html', title='Coach room', times=times)
  File "/home/kroof/PycharmProjects/adminFor/venv/lib/python3.8/site-packages/flask/templating.py", line 137, in render_template
    return _render(
  File "/home/kroof/PycharmProjects/adminFor/venv/lib/python3.8/site-packages/flask/templating.py", line 120, in _render
    rv = template.render(context)
  File "/home/kroof/PycharmProjects/adminFor/venv/lib/python3.8/site-packages/jinja2/environment.py", line 1090, in render
    self.environment.handle_exception()
  File "/home/kroof/PycharmProjects/adminFor/venv/lib/python3.8/site-packages/jinja2/environment.py", line 832, in handle_exception
    reraise(*rewrite_traceback_stack(source=source))
  File "/home/kroof/PycharmProjects/adminFor/venv/lib/python3.8/site-packages/jinja2/_compat.py", line 28, in reraise
    raise value.with_traceback(tb)
  File "/home/kroof/PycharmProjects/Gym_accounting_Flask/app/templates/coach_room.html", line 1, in top-level template code
    {% extends "base.html" %}
  File "/home/kroof/PycharmProjects/Gym_accounting_Flask/app/templates/base.html", line 41, in top-level template code
    {% block content %}{% endblock %}
  File "/home/kroof/PycharmProjects/Gym_accounting_Flask/app/templates/coach_room.html", line 6, in block "content"
    <li><p class="times">{{times.keys(i)}}</p></li>
jinja2.exceptions.UndefinedError: 'list object' has no attribute 'keys'
2021-05-22 17:18:08,363 INFO: Gym accounting [in /home/kroof/PycharmProjects/Gym_accounting_Flask/app/__init__.py:41]
2021-05-22 17:18:10,333 ERROR: Exception on /coach_room [GET] [in /home/kroof/PycharmProjects/adminFor/venv/lib/python3.8/site-packages/flask/app.py:1891]
Traceback (most recent call last):
  File "/home/kroof/PycharmProjects/adminFor/venv/lib/python3.8/site-packages/flask/app.py", line 2447, in wsgi_app
    response = self.full_dispatch_request()
  File "/home/kroof/PycharmProjects/adminFor/venv/lib/python3.8/site-packages/flask/app.py", line 1952, in full_dispatch_request
    rv = self.handle_user_exception(e)
  File "/home/kroof/PycharmProjects/adminFor/venv/lib/python3.8/site-packages/flask/app.py", line 1821, in handle_user_exception
    reraise(exc_type, exc_value, tb)
  File "/home/kroof/PycharmProjects/adminFor/venv/lib/python3.8/site-packages/flask/_compat.py", line 39, in reraise
    raise value
  File "/home/kroof/PycharmProjects/adminFor/venv/lib/python3.8/site-packages/flask/app.py", line 1950, in full_dispatch_request
    rv = self.dispatch_request()
  File "/home/kroof/PycharmProjects/adminFor/venv/lib/python3.8/site-packages/flask/app.py", line 1936, in dispatch_request
    return self.view_functions[rule.endpoint](**req.view_args)
  File "/home/kroof/PycharmProjects/adminFor/venv/lib/python3.8/site-packages/flask_login/utils.py", line 272, in decorated_view
    return func(*args, **kwargs)
  File "/home/kroof/PycharmProjects/Gym_accounting_Flask/app/routes.py", line 163, in coach_room
    return render_template('coach_room.html', title='Coach room', times=trainings)
  File "/home/kroof/PycharmProjects/adminFor/venv/lib/python3.8/site-packages/flask/templating.py", line 137, in render_template
    return _render(
  File "/home/kroof/PycharmProjects/adminFor/venv/lib/python3.8/site-packages/flask/templating.py", line 120, in _render
    rv = template.render(context)
  File "/home/kroof/PycharmProjects/adminFor/venv/lib/python3.8/site-packages/jinja2/environment.py", line 1090, in render
    self.environment.handle_exception()
  File "/home/kroof/PycharmProjects/adminFor/venv/lib/python3.8/site-packages/jinja2/environment.py", line 832, in handle_exception
    reraise(*rewrite_traceback_stack(source=source))
  File "/home/kroof/PycharmProjects/adminFor/venv/lib/python3.8/site-packages/jinja2/_compat.py", line 28, in reraise
    raise value.with_traceback(tb)
  File "/home/kroof/PycharmProjects/Gym_accounting_Flask/app/templates/coach_room.html", line 1, in top-level template code
    {% extends "base.html" %}
  File "/home/kroof/PycharmProjects/Gym_accounting_Flask/app/templates/base.html", line 41, in top-level template code
    {% block content %}{% endblock %}
  File "/home/kroof/PycharmProjects/Gym_accounting_Flask/app/templates/coach_room.html", line 6, in block "content"
    <li><p class="times">{{times.keys(i)}}</p></li>
TypeError: keys() takes no arguments (1 given)
2021-05-22 17:18:48,275 INFO: Gym accounting [in /home/kroof/PycharmProjects/Gym_accounting_Flask/app/__init__.py:41]
